Workbook

Sheet DADOS
A2: BANCO BARI - AÇÕES PASSIVAS
A3: ESCRITÓRIO | K3: AÇÕES PASSIVAS
A4: VERNALHA PEREIRA | B4: =COUNTIF('[1]BANCO - PASSIVAS'!A:A,DADOS!A4) -> #VALUE! | K4: PRODUTO
A5: ADVOCACIA SCHMITZ | B5: =COUNTIF('[1]BANCO - PASSIVAS'!A:A,DADOS!A5) -> #VALUE! | K5: CRÉDITO IMOBILIÁRIO | L5: =COUNTIF('[1]BANCO - PASSIVAS'!U:U,DADOS!K5) + COUNTIF('[2]HIPO - PASSIVAS'!U:U,DADOS!K5) + COUNTIF('[3]SEC - PASSIVAS'!V:V,DADOS!K5) -> #VALUE!
A6: JHONATAN DE SOUZA SILVA SOCIEDADE INDIVIDUAL DE ADVOCACIA | B6: =COUNTIF('[1]BANCO - PASSIVAS'!A:A,DADOS!A6) -> #VALUE! | K6: CRÉDITO CONSIGNADO | L6: =COUNTIF('[1]BANCO - PASSIVAS'!U:U,DADOS!K6) + COUNTIF('[2]HIPO - PASSIVAS'!U:U,DADOS!K6) + COUNTIF('[3]SEC - PASSIVAS'!V:V,DADOS!K6) -> #VALUE!
A7: OLIVEIRA PINTO E ADVOGADOS ASSOCIADOS | B7: =COUNTIF('[1]BANCO - PASSIVAS'!A:A,DADOS!A7) -> #VALUE! | K7: CONTA CORRENTE | L7: =COUNTIF('[1]BANCO - PASSIVAS'!U:U,DADOS!K7) + COUNTIF('[2]HIPO - PASSIVAS'!U:U,DADOS!K7) + COUNTIF('[3]SEC - PASSIVAS'!V:V,DADOS!K7) -> #VALUE!
A8: GABARDO E TERRA | B8: =COUNTIF('[1]BANCO - PASSIVAS'!A:A,DADOS!A8) -> #VALUE! | K8: CARTÃO DE CRÉDITO | L8: =COUNTIF('[1]BANCO - PASSIVAS'!U:U,DADOS!K8) + COUNTIF('[2]HIPO - PASSIVAS'!U:U,DADOS!K8) + COUNTIF('[3]SEC - PASSIVAS'!V:V,DADOS!K8) -> #VALUE!
A9: R. MENDONÇA SOCIEDADE DE ADVOGADOS | B9: =COUNTIF('[1]BANCO - PASSIVAS'!A:A,DADOS!A9) -> #VALUE! | K9: TRIBUTÁRIO | L9: =COUNTIF('[1]BANCO - PASSIVAS'!U:U,DADOS!K9) + COUNTIF('[2]HIPO - PASSIVAS'!U:U,DADOS!K9) + COUNTIF('[3]SEC - PASSIVAS'!V:V,DADOS!K9) -> #VALUE!
A10: Ferriani, Jamal, Fornazari, Sartori & Sanchez Advogados | B10: =COUNTIF('[1]BANCO - PASSIVAS'!A:A,DADOS!A10) -> #VALUE! | K10: COBRANÇA | L10: =COUNTIF('[1]BANCO - PASSIVAS'!U:U,DADOS!K10) + COUNTIF('[2]HIPO - PASSIVAS'!U:U,DADOS!K10) + COUNTIF('[3]SEC - PASSIVAS'!V:V,DADOS!K10) -> #VALUE!
A11: NELSON WILIANS ADVOGADOS | B11: =COUNTIF('[1]BANCO - PASSIVAS'!A:A,DADOS!A11) -> #VALUE!
A12: JURÍDICO INTERNO | B12: =COUNTIF('[1]BANCO - PASSIVAS'!A:A,DADOS!A12) -> #VALUE!
A13: Maran, Gehlen & Advogados Associados | B13: =COUNTIF('[1]BANCO - PASSIVAS'!A:A,DADOS!A13) -> #VALUE!
A14: FILLA E MUNHOZ DA ROCHA ADVOGADOS ASSOCIADOS | B14: =COUNTIF('[1]BANCO - PASSIVAS'!A:A,DADOS!A14) -> #VALUE!
A15: TOTAL | B15: =SUM(B4:B14) -> #VALUE!
A17: BANCO BARI - AÇÕES ATIVAS | K17: AÇÕES ATIVAS
A18: ESCRITÓRIO | K18: PRODUTO
A19: VERNALHA PEREIRA | B19: =COUNTIF('[4]BANCO - ATIVAS'!A:A,DADOS!A19) -> #VALUE! | K19: CRÉDITO IMOBILIÁRIO | L19: =COUNTIF('[4]BANCO - ATIVAS'!V:V,DADOS!K19) + COUNTIF('[5]HIPO - ATIVAS'!V:V,DADOS!K19) + COUNTIF('[6]SEC - ATIVAS'!W:W,DADOS!K19) -> #VALUE!
A20: ADVOCACIA SCHMITZ | B20: =COUNTIF('[4]BANCO - ATIVAS'!A:A,DADOS!A20) -> #VALUE! | K20: CRÉDITO CONSIGNADO | L20: =COUNTIF('[4]BANCO - ATIVAS'!V:V,DADOS!K20) + COUNTIF('[5]HIPO - ATIVAS'!V:V,DADOS!K20) + COUNTIF('[6]SEC - ATIVAS'!W:W,DADOS!K20) -> #VALUE!
A21: JHONATAN DE SOUZA SILVA SOCIEDADE INDIVIDUAL DE ADVOCACIA | B21: =COUNTIF('[4]BANCO - ATIVAS'!A:A,DADOS!A21) -> #VALUE! | K21: CONTA CORRENTE | L21: =COUNTIF('[4]BANCO - ATIVAS'!V:V,DADOS!K21) + COUNTIF('[5]HIPO - ATIVAS'!V:V,DADOS!K21) + COUNTIF('[6]SEC - ATIVAS'!W:W,DADOS!K21) -> #VALUE!
A22: OLIVEIRA PINTO E ADVOGADOS ASSOCIADOS | B22: =COUNTIF('[4]BANCO - ATIVAS'!A:A,DADOS!A22) -> #VALUE! | K22: CARTÃO DE CRÉDITO | L22: =COUNTIF('[4]BANCO - ATIVAS'!V:V,DADOS!K22) + COUNTIF('[5]HIPO - ATIVAS'!V:V,DADOS!K22) + COUNTIF('[6]SEC - ATIVAS'!W:W,DADOS!K22) -> #VALUE!
A23: GABARDO E TERRA | B23: =COUNTIF('[4]BANCO - ATIVAS'!A:A,DADOS!A23) -> #VALUE! | G23: TOTAL | H23: =B15+B30+B46+B62+B78+B94 -> #VALUE! | K23: TRIBUTÁRIO | L23: =COUNTIF('[4]BANCO - ATIVAS'!V:V,DADOS!K23) + COUNTIF('[5]HIPO - ATIVAS'!V:V,DADOS!K23) + COUNTIF('[6]SEC - ATIVAS'!W:W,DADOS!K23) -> #VALUE!
A24: R. MENDONÇA SOCIEDADE DE ADVOGADOS | B24: =COUNTIF('[4]BANCO - ATIVAS'!A:A,DADOS!A24) -> #VALUE! | K24: COBRANÇA | L24: =COUNTIF('[4]BANCO - ATIVAS'!V:V,DADOS!K24) + COUNTIF('[5]HIPO - ATIVAS'!V:V,DADOS!K24) + COUNTIF('[6]SEC - ATIVAS'!W:W,DADOS!K24) -> #VALUE!
A25: Ferriani, Jamal, Fornazari, Sartori & Sanchez Advogados | B25: =COUNTIF('[4]BANCO - ATIVAS'!A:A,DADOS!A25) -> #VALUE!
A26: NELSON WILIANS ADVOGADOS | B26: =COUNTIF('[4]BANCO - ATIVAS'!A:A,DADOS!A26) -> #VALUE!
A27: JURÍDICO INTERNO | B27: =COUNTIF('[4]BANCO - ATIVAS'!A:A,DADOS!A27) -> #VALUE!
A28: Maran, Gehlen & Advogados Associados | B28: =COUNTIF('[4]BANCO - ATIVAS'!A:A,DADOS!A28) -> #VALUE!
A29: FILLA E MUNHOZ DA ROCHA ADVOGADOS ASSOCIADOS | B29: =COUNTIF('[4]BANCO - ATIVAS'!A:A,DADOS!A29) -> #VALUE!
A30: TOTAL | B30: =SUM(B19:B29) -> #VALUE!
A33: HIPOTECÁRIA - AÇÕES PASSIVAS
A34: ESCRITÓRIO
A35: VERNALHA PEREIRA | B35: =COUNTIF('[2]HIPO - PASSIVAS'!A:A,DADOS!A35) -> #VALUE!
A36: ADVOCACIA SCHMITZ | B36: =COUNTIF('[2]HIPO - PASSIVAS'!A:A,DADOS!A36) -> #VALUE!
A37: JHONATAN DE SOUZA SILVA SOCIEDADE INDIVIDUAL DE ADVOCACIA | B37: =COUNTIF('[2]HIPO - PASSIVAS'!A:A,DADOS!A37) -> #VALUE!
A38: OLIVEIRA PINTO E ADVOGADOS ASSOCIADOS | B38: =COUNTIF('[2]HIPO - PASSIVAS'!A:A,DADOS!A38) -> #VALUE!
A39: GABARDO E TERRA | B39: =COUNTIF('[2]HIPO - PASSIVAS'!A:A,DADOS!A39) -> #VALUE!
A40: R. MENDONÇA SOCIEDADE DE ADVOGADOS | B40: =COUNTIF('[2]HIPO - PASSIVAS'!A:A,DADOS!A40) -> #VALUE!
A41: Ferriani, Jamal, Fornazari, Sartori & Sanchez Advogados | B41: =COUNTIF('[2]HIPO - PASSIVAS'!A:A,DADOS!A41) -> #VALUE!
A42: NELSON WILIANS ADVOGADOS | B42: =COUNTIF('[2]HIPO - PASSIVAS'!A:A,DADOS!A42) -> #VALUE!
A43: JURÍDICO INTERNO | B43: =COUNTIF('[2]HIPO - PASSIVAS'!A:A,DADOS!A43) -> #VALUE!
A44: Maran, Gehlen & Advogados Associados | B44: =COUNTIF('[2]HIPO - PASSIVAS'!A:A,DADOS!A44) -> #VALUE!
...
